Workbook

Sheet Dashboard
A1: Vendor Master & AP Data Governance - Dashboard
A2: Finance Operations | Synthetic data | All KPIs are live formulas
A3: Vendor master KPI | B3: Value
A4: Raw vendor records | B4: =COUNTA(Vendor_Master_Raw!A2:A229) -> 228
A5: Golden (unique) vendors | B5: =COUNTA(Vendor_Master_Golden!A2:A208) -> 207
A6: Duplicate records merged | B6: =B4-B5 -> 21
A7: Avg DQ pass % (before) | B7: =DQ_Scorecard!E13 -> 0.77741228
A8: Avg DQ pass % (after) | B8: =DQ_Scorecard!H13 -> 0.91727053
A9: Vendors needing steward action | B9: =COUNTA(Steward_Queue!A2:A86) -> 85
A10: High-priority steward cases | B10: =COUNTIF(Steward_Queue!F2:F86,"High") -> 71
A11: Near-duplicate pairs to review | B11: =COUNTA(Duplicate_Review!A2:A10) -> 9
A13: AP invoice KPI | B13: Count | C13: Amount (INR)
A14: Total invoices | B14: =COUNTA(AP_Invoices_Recon!A2:A511) -> 510 | C14: =SUM(AP_Invoices_Recon!D2:D511) -> 47492000
A15: Orphan vendor ID (not in master) | B15: =COUNTIF(AP_Invoices_Recon!I2:I511,"Orphan Vendor ID") -> 10 | C15: =SUMIFS(AP_Invoices_Recon!D2:D511,AP_Invoices_Recon!I2:I511,"Orphan Vendor ID") -> 803600
A16: Invoices on inactive vendors | B16: =COUNTIF(AP_Invoices_Recon!I2:I511,"Inactive Vendor") -> 65 | C16: =SUMIFS(AP_Invoices_Recon!D2:D511,AP_Invoices_Recon!I2:I511,"Inactive Vendor") -> 6245900
A17: Duplicate invoices (after MDM) | B17: =COUNTIF(AP_Invoices_Recon!L2:L511,"Duplicate") -> 12 | C17: =SUMIFS(AP_Invoices_Recon!D2:D511,AP_Invoices_Recon!L2:L511,"Duplicate") -> 997600
A18: of which duplicate already Paid | B18: =COUNTIFS(AP_Invoices_Recon!L2:L511,"Duplicate",AP_Invoices_Recon!E2:E511,"Paid") -> 6 | C18: =SUMIFS(AP_Invoices_Recon!D2:D511,AP_Invoices_Recon!L2:L511,"Duplicate",AP_Invoices_Recon!E2:E511,"Paid") -> 599500
A19: of which still Pending (stoppable) | B19: =COUNTIFS(AP_Invoices_Recon!L2:L511,"Duplicate",AP_Invoices_Recon!E2:E511,"Pending") -> 6 | C19: =SUMIFS(AP_Invoices_Recon!D2:D511,AP_Invoices_Recon!L2:L511,"Duplicate",AP_Invoices_Recon!E2:E511,"Pending") -> 398100
A20: Duplicates found ONLY after vendor merge | B20: =COUNTIF(AP_Invoices_Recon!M2:M511,"Yes") -> 6 | C20: =SUMIFS(AP_Invoices_Recon!D2:D511,AP_Invoices_Recon!M2:M511,"Yes") -> 555400

Sheet DQ_Scorecard
A1: Vendor Master Data Quality Scorecard - Before vs After
A2: All figures are live formulas over Vendor_Master_Raw (before) and Vendor_Master_Golden (after).
A4: Rule | B4: Check column | C4: Records (Before) | D4: Valid (Before) | E4: Pass % (Before) | F4: Records (After) | G4: Valid (After) | H4: Pass % (After) | I4: Improvement (pts) | J4: Open issues (After)
A5: PAN | B5: PAN_Check | C5: =COUNTA(Vendor_Master_Raw!$A$2:$A$229) -> 228 | D5: =COUNTIF(Vendor_Master_Raw!$M$2:$M$229,"Valid") -> 190 | E5: =IF(C5=0,0,D5/C5) -> 0.83333333 | F5: =COUNTA(Vendor_Master_Golden!$A$2:$A$208) -> 207 | G5: =COUNTIF(Vendor_Master_Golden!$M$2:$M$208,"Valid") -> 183 | H5: =IF(F5=0,0,G5/F5) -> 0.88405797 | I5: =(H5-E5)*100 -> 5.0724638 | J5: =F5-G5 -> 24
A6: GSTIN | B6: GSTIN_Check | C6: =COUNTA(Vendor_Master_Raw!$A$2:$A$229) -> 228 | D6: =COUNTIF(Vendor_Master_Raw!$N$2:$N$229,"Valid") -> 166 | E6: =IF(C6=0,0,D6/C6) -> 0.72807018 | F6: =COUNTA(Vendor_Master_Golden!$A$2:$A$208) -> 207 | G6: =COUNTIF(Vendor_Master_Golden!$N$2:$N$208,"Valid") -> 155 | H6: =IF(F6=0,0,G6/F6) -> 0.74879227 | I6: =(H6-E6)*100 -> 2.0722095 | J6: =F6-G6 -> 52
A7: Email | B7: Email_Check | C7: =COUNTA(Vendor_Master_Raw!$A$2:$A$229) -> 228 | D7: =COUNTIF(Vendor_Master_Raw!$O$2:$O$229,"Valid") -> 209 | E7: =IF(C7=0,0,D7/C7) -> 0.91666667 | F7: =COUNTA(Vendor_Master_Golden!$A$2:$A$208) -> 207 | G7: =COUNTIF(Vendor_Master_Golden!$O$2:$O$208,"Valid") -> 190 | H7: =IF(F7=0,0,G7/F7) -> 0.9178744 | I7: =(H7-E7)*100 -> 0.12077295 | J7: =F7-G7 -> 17
A8: Phone | B8: Phone_Check | C8: =COUNTA(Vendor_Master_Raw!$A$2:$A$229) -> 228 | D8: =COUNTIF(Vendor_Master_Raw!$P$2:$P$229,"Valid") -> 211 | E8: =IF(C8=0,0,D8/C8) -> 0.9254386 | F8: =COUNTA(Vendor_Master_Golden!$A$2:$A$208) -> 207 | G8: =COUNTIF(Vendor_Master_Golden!$P$2:$P$208,"Valid") -> 196 | H8: =IF(F8=0,0,G8/F8) -> 0.9468599 | I8: =(H8-E8)*100 -> 2.1421307 | J8: =F8-G8 -> 11
A9: Bank Account | B9: Bank_Check | C9: =COUNTA(Vendor_Master_Raw!$A$2:$A$229) -> 228 | D9: =COUNTIF(Vendor_Master_Raw!$Q$2:$Q$229,"Valid") -> 216 | E9: =IF(C9=0,0,D9/C9) -> 0.94736842 | F9: =COUNTA(Vendor_Master_Golden!$A$2:$A$208) -> 207 | G9: =COUNTIF(Vendor_Master_Golden!$Q$2:$Q$208,"Valid") -> 197 | H9: =IF(F9=0,0,G9/F9) -> 0.95169082 | I9: =(H9-E9)*100 -> 0.43224002 | J9: =F9-G9 -> 10
A10: IFSC | B10: IFSC_Check | C10: =COUNTA(Vendor_Master_Raw!$A$2:$A$229) -> 228 | D10: =COUNTIF(Vendor_Master_Raw!$R$2:$R$229,"Valid") -> 191 | E10: =IF(C10=0,0,D10/C10) -> 0.8377193 | F10: =COUNTA(Vendor_Master_Golden!$A$2:$A$208) -> 207 | G10: =COUNTIF(Vendor_Master_Golden!$R$2:$R$208,"Valid") -> 184 | H10: =IF(F10=0,0,G10/F10) -> 0.88888889 | I10: =(H10-E10)*100 -> 5.1169591 | J10: =F10-G10 -> 23
A11: Country | B11: Country_Check | C11: =COUNTA(Vendor_Master_Raw!$A$2:$A$229) -> 228 | D11: =COUNTIF(Vendor_Master_Raw!$S$2:$S$229,"Valid") -> 163 | E11: =IF(C11=0,0,D11/C11) -> 0.71491228 | F11: =COUNTA(Vendor_Master_Golden!$A$2:$A$208) -> 207 | G11: =COUNTIF(Vendor_Master_Golden!$S$2:$S$208,"Valid") -> 207 | H11: =IF(F11=0,0,G11/F11) -> 1 | I11: =(H11-E11)*100 -> 28.508772 | J11: =F11-G11 -> 0
A12: Payment Terms | B12: Terms_Check | C12: =COUNTA(Vendor_Master_Raw!$A$2:$A$229) -> 228 | D12: =COUNTIF(Vendor_Master_Raw!$T$2:$T$229,"Valid") -> 72 | E12: =IF(C12=0,0,D12/C12) -> 0.31578947 | F12: =COUNTA(Vendor_Master_Golden!$A$2:$A$208) -> 207 | G12: =COUNTIF(Vendor_Master_Golden!$T$2:$T$208,"Valid") -> 207 | H12: =IF(F12=0,0,G12/F12) -> 1 | I12: =(H12-E12)*100 -> 68.421053 | J12: =F12-G12 -> 0
A13: Average pass % | E13: =AVERAGE(E5:E12) -> 0.77741228 | H13: =AVERAGE(H5:H12) -> 0.91727053 | I13: =(H13-E13)*100 -> 13.985825 | J13: =SUM(J5:J12) -> 137
A14: Records with zero issues | D14: =COUNTIF(Vendor_Master_Raw!$U$2:$U$229,0) -> 27 | E14: =D14/C5 -> 0.11842105 | G14: =COUNTIF(Vendor_Master_Golden!$U$2:$U$208,0) -> 122 | H14: =G14/F5 -> 0.58937198 | I14: =(H14-E14)*100 -> 47.095093
A16: Note: 'After' improves on format/standardisation and duplicates. Missing or unverifiable PAN, GSTIN, bank and IFSC values are NOT invented - they go to Steward_Queue.

Sheet DQ_Rules
A1: Rule_ID | B1: Field / Area | C1: Validation Rule | D1: Severity | E1: Treatment
A2: R01 | B2: PAN | C2: Not blank; 10 chars: 5 capital letters + 4 digits + 1 capital letter | D2: High | E2: Uppercase automatically; blanks need vendor document
A3: R02 | B3: GSTIN | C3: 15 chars, 14th char = Z, characters 3-12 must equal the vendor's PAN. Fails as 'PAN Mismatch' if PAN is missing or different | D3: High | E3: Cannot be auto-fixed - confirm with vendor / GST portal
A4: R03 | B4: Email | C4: Not blank; contains @; a dot after the @; no spaces | D4: Medium | E4: Lowercase automatically; invalid needs vendor confirmation
A5: R04 | B5: Phone | C5: Digits only after removing space, hyphen, +; 10 digits (or 12 starting 91); first digit 6-9 | D5: Medium | E5: Re-formatted to +91 XXXXXXXXXX when valid
A6: R05 | B6: Bank_Account | C6: Not blank; digits only; 9-18 digits | D6: High | E6: Cannot be auto-fixed - needs bank proof
A7: R06 | B7: IFSC | C7: 11 chars: 4 capital letters + '0' + 6 characters | D7: High | E7: Uppercase automatically; invalid needs bank proof
A8: R07 | B8: Country | C8: Must equal 'India' (standard value) | D8: Low | E8: IN / INDIA / india mapped to India
A9: R08 | B9: Payment_Terms | C9: Standard values only: Net 15 / Net 30 / Net 45 / Net 60 | D9: Low | E9: 30D, NET30, 30 Days mapped to Net 30
A10: R09 | B10: Duplicate vendor | C10: Same normalised name (case, punctuation, Pvt/Private/Ltd/Limited/LLP ignored) OR same valid PAN | D10: High | E10: Auto-merged to one golden record; most complete record survives
A11: R10 | B11: Near-duplicate | C11: Name similarity >= 0.90 but no exact name/PAN match | D11: Medium | E11: Listed in Duplicate_Review - NOT auto-merged
A12: R11 | B12: Invoice vendor | C12: Invoice Vendor_ID must exist in vendor master | D12: High | E12: Orphan IDs routed to vendor onboarding
A13: R12 | B13: Duplicate invoice | C13: Same golden vendor + Invoice_No + amount appears more than once | D13: High | E13: Hold duplicate before payment run

Sheet Vendor_Master_Raw
A1: Vendor_ID | B1: Vendor_Name | C1: PAN | D1: GSTIN | E1: Email | F1: Phone | G1: Bank_Account | H1: IFSC | I1: Country | J1: Payment_Terms | K1: Status | L1: Created_Date | M1: PAN_Check | N1: GSTIN_Check | O1: Email_Check | P1: Phone_Check | Q1: Bank_Check | R1: IFSC_Check | S1: Country_Check | T1: Terms_Check | U1: Issue_Count | V1: Phone_Digits_(helper) | W1: Golden_Vendor_ID (from Python de-dup) | X1: Dup_Flag
A2: V1079 | B2: Falcon Landscaping Pvt Ltd | C2: NPMCL8617Z | D2: 19NPMCL8617Z1ZO | E2: accounts@falconlandscaping.in | F2: +91 91040 54115 | G2: 621815997062 | H2: KKBK0620153 | I2: IN | J2: net 30 | K2: Active | L2: 2025-03-19 | M2: =IF(TRIM(C2)="","Missing",IF(AND(LEN(TRIM(C2))=10,SUMPRODUCT(--(CODE(MID(TRIM(C2),{1,2,3,4,5,10},1))>=65),--(CODE(MID(TRIM(C2),{1,2,3,4,5,10},1))<=90))=6,ISNUMBER(--MID(TRIM(C2),6,4))),"Valid","Invalid")) -> Valid | N2: =IF(TRIM(D2)="","Missing",IF(AND(LEN(TRIM(D2))=15,MID(TRIM(D2),14,1)="Z"),IF(AND(TRIM(C2)<>"",MID(TRIM(D2),3,10)=TRIM(C2)),"Valid","PAN Mismatch"),"Invalid")) -> Valid | O2: =IF(TRIM(E2)="","Missing",IF(AND(ISNUMBER(FIND("@",E2)),ISERROR(FIND(" ",TRIM(E2))),IFERROR(FIND(".",E2,FIND("@",E2)),0)>0),"Valid","Invalid")) -> Valid | P2: =IF(TRIM(F2)="","Missing",IFERROR(IF(AND(ISNUMBER(--V2),OR(LEN(V2)=10,AND(LEN(V2)=12,LEFT(V2,2)="91")),VALUE(LEFT(RIGHT(V2,10),1))>=6),"Valid","Invalid"),"Invalid")) -> Valid | Q2: =IF(TRIM(G2)="","Missing",IFERROR(IF(AND(ISNUMBER(--TRIM(G2)),LEN(TRIM(G2))>=9,LEN(TRIM(G2))<=18,ISERROR(FIND(".",G2))),"Valid","Invalid"),"Invalid")) -> Valid | R2: =IF(TRIM(H2)="","Missing",IF(AND(LEN(TRIM(H2))=11,SUMPRODUCT(--(CODE(MID(TRIM(H2),{1,2,3,4},1))>=65),--(CODE(MID(TRIM(H2),{1,2,3,4},1))<=90))=4,MID(TRIM(H2),5,1)="0"),"Valid","Invalid")) -> Valid | S2: =IF(TRIM(I2)="","Missing",IF(EXACT(TRIM(I2),"India"),"Valid","Invalid")) -> Invalid | T2: =IF(TRIM(J2)="","Missing",IF(OR(EXACT(TRIM(J2),"Net 15"),EXACT(TRIM(J2),"Net 30"),EXACT(TRIM(J2),"Net 45"),EXACT(TRIM(J2),"Net 60")),"Valid","Invalid")) -> Invalid | U2: =COUNTIF(M2:T2,"<>Valid") -> 2 | V2: =SUBSTITUTE(SUBSTITUTE(SUBSTITUTE(F2," ",""),"-",""),"+","") -> 919104054115 | W2: V1079 | X2: =IF(COUNTIF($W$2:$W$229,W2)>1,"Duplicate","Unique") -> Duplicate
A3: V1109 | B3: Sunrise Housekeeping LLP | C3: QAXCW1184X | D3: 19QAXCW1184X1Z9 | E3: ACCOUNTS@SUNRISEHOUSEKEEPING.IN | F3: +91 84393 76904 | H3: KKBK0476973 | I3: India | J3: NET45 | K3: Active | L3: 2024-02-23 | M3: =IF(TRIM(C3)="","Missing",IF(AND(LEN(TRIM(C3))=10,SUMPRODUCT(--(CODE(MID(TRIM(C3),{1,2,3,4,5,10},1))>=65),--(CODE(MID(TRIM(C3),{1,2,3,4,5,10},1))<=90))=6,ISNUMBER(--MID(TRIM(C3),6,4))),"Valid","Invalid")) -> Valid | N3: =IF(TRIM(D3)="","Missing",IF(AND(LEN(TRIM(D3))=15,MID(TRIM(D3),14,1)="Z"),IF(AND(TRIM(C3)<>"",MID(TRIM(D3),3,10)=TRIM(C3)),"Valid","PAN Mismatch"),"Invalid")) -> Valid | O3: =IF(TRIM(E3)="","Missing",IF(AND(ISNUMBER(FIND("@",E3)),ISERROR(FIND(" ",TRIM(E3))),IFERROR(FIND(".",E3,FIND("@",E3)),0)>0),"Valid","Invalid")) -> Valid | P3: =IF(TRIM(F3)="","Missing",IFERROR(IF(AND(ISNUMBER(--V3),OR(LEN(V3)=10,AND(LEN(V3)=12,LEFT(V3,2)="91")),VALUE(LEFT(RIGHT(V3,10),1))>=6),"Valid","Invalid"),"Invalid")) -> Valid | Q3: =IF(TRIM(G3)="","Missing",IFERROR(IF(AND(ISNUMBER(--TRIM(G3)),LEN(TRIM(G3))>=9,LEN(TRIM(G3))<=18,ISERROR(FIND(".",G3))),"Valid","Invalid"),"Invalid")) -> Missing | R3: =IF(TRIM(H3)="","Missing",IF(AND(LEN(TRIM(H3))=11,SUMPRODUCT(--(CODE(MID(TRIM(H3),{1,2,3,4},1))>=65),--(CODE(MID(TRIM(H3),{1,2,3,4},1))<=90))=4,MID(TRIM(H3),5,1)="0"),"Valid","Invalid")) -> Valid | S3: =IF(TRIM(I3)="","Missing",IF(EXACT(TRIM(I3),"India"),"Valid","Invalid")) -> Valid | T3: =IF(TRIM(J3)="","Missing",IF(OR(EXACT(TRIM(J3),"Net 15"),EXACT(TRIM(J3),"Net 30"),EXACT(TRIM(J3),"Net 45"),EXACT(TRIM(J3),"Net 60")),"Valid","Invalid")) -> Invalid | U3: =COUNTIF(M3:T3,"<>Valid") -> 2 | V3: =SUBSTITUTE(SUBSTITUTE(SUBSTITUTE(F3," ",""),"-",""),"+","") -> 918439376904 | W3: V1109 | X3: =IF(COUNTIF($W$2:$W$229,W3)>1,"Duplicate","Unique") -> Unique
A4: V1054 | B4: Quantum Stationers Pvt Ltd | C4: IRSCS6423K | D4: 29IRSCS6423K1ZY | E4: accounts@quantumstationers.in | F4: 98547-77252 | G4: 872808010062 | H4: ICIC0120387 | I4: IN | J4: Net 45 | K4: Inactive | L4: 2024-06-02 | M4: =IF(TRIM(C4)="","Missing",IF(AND(LEN(TRIM(C4))=10,SUMPRODUCT(--(CODE(MID(TRIM(C4),{1,2,3,4,5,10},1))>=65),--(CODE(MID(TRIM(C4),{1,2,3,4,5,10},1))<=90))=6,ISNUMBER(--MID(TRIM(C4),6,4))),"Valid","Invalid")) -> Valid | N4: =IF(TRIM(D4)="","Missing",IF(AND(LEN(TRIM(D4))=15,MID(TRIM(D4),14,1)="Z"),IF(AND(TRIM(C4)<>"",MID(TRIM(D4),3,10)=TRIM(C4)),"Valid","PAN Mismatch"),"Invalid")) -> Valid | O4: =IF(TRIM(E4)="","Missing",IF(AND(ISNUMBER(FIND("@",E4)),ISERROR(FIND(" ",TRIM(E4))),IFERROR(FIND(".",E4,FIND("@",E4)),0)>0),"Valid","Invalid")) -> Valid | P4: =IF(TRIM(F4)="","Missing",IFERROR(IF(AND(ISNUMBER(--V4),OR(LEN(V4)=10,AND(LEN(V4)=12,LEFT(V4,2)="91")),VALUE(LEFT(RIGHT(V4,10),1))>=6),"Valid","Invalid"),"Invalid")) -> Valid | Q4: =IF(TRIM(G4)="","Missing",IFERROR(IF(AND(ISNUMBER(--TRIM(G4)),LEN(TRIM(G4))>=9,LEN(TRIM(G4))<=18,ISERROR(FIND(".",G4))),"Valid","Invalid"),"Invalid")) -> Valid | R4: =IF(TRIM(H4)="","Missing",IF(AND(LEN(TRIM(H4))=11,SUMPRODUCT(--(CODE(MID(TRIM(H4),{1,2,3,4},1))>=65),--(CODE(MID(TRIM(H4),{1,2,3,4},1))<=90))=4,MID(TRIM(H4),5,1)="0"),"Valid","Invalid")) -> Valid | S4: =IF(TRIM(I4)="","Missing",IF(EXACT(TRIM(I4),"India"),"Valid","Invalid")) -> Invalid | T4: =IF(TRIM(J4)="","Missing",IF(OR(EXACT(TRIM(J4),"Net 15"),EXACT(TRIM(J4),"Net 30"),EXACT(TRIM(J4),"Net 45"),EXACT(TRIM(J4),"Net 60")),"Valid","Invalid")) -> Valid | U4: =COUNTIF(M4:T4,"<>Valid") -> 1 | V4: =SUBSTITUTE(SUBSTITUTE(SUBSTITUTE(F4," ",""),"-",""),"+","") -> 9854777252 | W4: V1054 | X4: =IF(COUNTIF($W$2:$W$229,W4)>1,"Duplicate","Unique") -> Duplicate
A5: V1209 | B5: BLUEWAVE FACILITY SERVICES L.L.P. | C5: WYUCY2965O | D5: 07WYUCY2965O1ZI | E5: accounts@bluewavefacilityservices.in | F5: 79543-16526 | G5: 93008931734206 | H5: KKBK0694215 | I5: INDIA | J5: NET30 | K5: Active | L5: 2021-04-22 | M5: =IF(TRIM(C5)="","Missing",IF(AND(LEN(TRIM(C5))=10,SUMPRODUCT(--(CODE(MID(TRIM(C5),{1,2,3,4,5,10},1))>=65),--(CODE(MID(TRIM(C5),{1,2,3,4,5,10},1))<=90))=6,ISNUMBER(--MID(TRIM(C5),6,4))),"Valid","Invalid")) -> Valid | N5: =IF(TRIM(D5)="","Missing",IF(AND(LEN(TRIM(D5))=15,MID(TRIM(D5),14,1)="Z"),IF(AND(TRIM(C5)<>"",MID(TRIM(D5),3,10)=TRIM(C5)),"Valid","PAN Mismatch"),"Invalid")) -> Valid | O5: =IF(TRIM(E5)="","Missing",IF(AND(ISNUMBER(FIND("@",E5)),ISERROR(FIND(" ",TRIM(E5))),IFERROR(FIND(".",E5,FIND("@",E5)),0)>0),"Valid","Invalid")) -> Valid | P5: =IF(TRIM(F5)="","Missing",IFERROR(IF(AND(ISNUMBER(--V5),OR(LEN(V5)=10,AND(LEN(V5)=12,LEFT(V5,2)="91")),VALUE(LEFT(RIGHT(V5,10),1))>=6),"Valid","Invalid"),"Invalid")) -> Valid | Q5: =IF(TRIM(G5)="","Missing",IFERROR(IF(AND(ISNUMBER(--TRIM(G5)),LEN(TRIM(G5))>=9,LEN(TRIM(G5))<=18,ISERROR(FIND(".",G5))),"Valid","Invalid"),"Invalid")) -> Valid | R5: =IF(TRIM(H5)="","Missing",IF(AND(LEN(TRIM(H5))=11,SUMPRODUCT(--(CODE(MID(TRIM(H5),{1,2,3,4},1))>=65),--(CODE(MID(TRIM(H5),{1,2,3,4},1))<=90))=4,MID(TRIM(H5),5,1)="0"),"Valid","Invalid")) -> Valid | S5: =IF(TRIM(I5)="","Missing",IF(EXACT(TRIM(I5),"India"),"Valid","Invalid")) -> Invalid | T5: =IF(TRIM(J5)="","Missing",IF(OR(EXACT(TRIM(J5),"Net 15"),EXACT(TRIM(J5),"Net 30"),EXACT(TRIM(J5),"Net 45"),EXACT(TRIM(J5),"Net 60")),"Valid","Invalid")) -> Invalid | U5: =COUNTIF(M5:T5,"<>Valid") -> 2 | V5: =SUBSTITUTE(SUBSTITUTE(SUBSTITUTE(F5," ",""),"-",""),"+","") -> 7954316526 | W5: V1174 | X5: =IF(COUNTIF($W$2:$W$229,W5)>1,"Duplicate","Unique") -> Duplicate
A6: V1137 | B6: Redwood Electricals Private Limited | C6: UGKCG3448K | D6: 19UGKCG3448K | E6: accounts@redwoodelectricals.in | F6: +91 82241 09881 | G6: 858542493214 | H6: KKBK0587020 | I6: IN | J6: Net 60 | K6: Active | L6: 2019-07-26 | M6: =IF(TRIM(C6)="","Missing",IF(AND(LEN(TRIM(C6))=10,SUMPRODUCT(--(CODE(MID(TRIM(C6),{1,2,3,4,5,10},1))>=65),--(CODE(MID(TRIM(C6),{1,2,3,4,5,10},1))<=90))=6,ISNUMBER(--MID(TRIM(C6),6,4))),"Valid","Invalid")) -> Valid | N6: =IF(TRIM(D6)="","Missing",IF(AND(LEN(TRIM(D6))=15,MID(TRIM(D6),14,1)="Z"),IF(AND(TRIM(C6)<>"",MID(TRIM(D6),3,10)=TRIM(C6)),"Valid","PAN Mismatch"),"Invalid")) -> Invalid | O6: =IF(TRIM(E6)="","Missing",IF(AND(ISNUMBER(FIND("@",E6)),ISERROR(FIND(" ",TRIM(E6))),IFERROR(FIND(".",E6,FIND("@",E6)),0)>0),"Valid","Invalid")) -> Valid | P6: =IF(TRIM(F6)="","Missing",IFERROR(IF(AND(ISNUMBER(--V6),OR(LEN(V6)=10,AND(LEN(V6)=12,LEFT(V6,2)="91")),VALUE(LEFT(RIGHT(V6,10),1))>=6),"Valid","Invalid"),"Invalid")) -> Valid | Q6: =IF(TRIM(G6)="","Missing",IFERROR(IF(AND(ISNUMBER(--TRIM(G6)),LEN(TRIM(G6))>=9,LEN(TRIM(G6))<=18,ISERROR(FIND(".",G6))),"Valid","Invalid"),"Invalid")) -> Valid | R6: =IF(TRIM(H6)="","Missing",IF(AND(LEN(TRIM(H6))=11,SUMPRODUCT(--(CODE(MID(TRIM(H6),{1,2,3,4},1))>=65),--(CODE(MID(TRIM(H6),{1,2,3,4},1))<=90))=4,MID(TRIM(H6),5,1)="0"),"Valid","Invalid")) -> Valid | S6: =IF(TRIM(I6)="","Missing",IF(EXACT(TRIM(I6),"India"),"Valid","Invalid")) -> Invalid | T6: =IF(TRIM(J6)="","Missing",IF(OR(EXACT(TRIM(J6),"Net 15"),EXACT(TRIM(J6),"Net 30"),EXACT(TRIM(J6),"Net 45"),EXACT(TRIM(J6),"Net 60")),"Valid","Invalid")) -> Valid | U6: =COUNTIF(M6:T6,"<>Valid") -> 2 | V6: =SUBSTITUTE(SUBSTITUTE(SUBSTITUTE(F6," ",""),"-",""),"+","") -> 918224109881 | W6: V1137 | X6: =IF(COUNTIF($W$2:$W$229,W6)>1,"Duplicate","Unique") -> Unique
A7: V1047 | B7: Nova Pest Control Private Limited | C7: YCUCS3802N | D7: 19YCUCS3802N1ZL | E7: accounts@novapestcontrol.in | F7: +91 97240 04991 | G7: 4788728743152 | H7: UTIB0420549 | I7: INDIA | J7: Net 30 | K7: Active | L7: 2023-07-19 | M7: =IF(TRIM(C7)="","Missing",IF(AND(LEN(TRIM(C7))=10,SUMPRODUCT(--(CODE(MID(TRIM(C7),{1,2,3,4,5,10},1))>=65),--(CODE(MID(TRIM(C7),{1,2,3,4,5,10},1))<=90))=6,ISNUMBER(--MID(TRIM(C7),6,4))),"Valid","Invalid")) -> Valid | N7: =IF(TRIM(D7)="","Missing",IF(AND(LEN(TRIM(D7))=15,MID(TRIM(D7),14,1)="Z"),IF(AND(TRIM(C7)<>"",MID(TRIM(D7),3,10)=TRIM(C7)),"Valid","PAN Mismatch"),"Invalid")) -> Valid | O7: =IF(TRIM(E7)="","Missing",IF(AND(ISNUMBER(FIND("@",E7)),ISERROR(FIND(" ",TRIM(E7))),IFERROR(FIND(".",E7,FIND("@",E7)),0)>0),"Valid","Invalid")) -> Valid | P7: =IF(TRIM(F7)="","Missing",IFERROR(IF(AND(ISNUMBER(--V7),OR(LEN(V7)=10,AND(LEN(V7)=12,LEFT(V7,2)="91")),VALUE(LEFT(RIGHT(V7,10),1))>=6),"Valid","Invalid"),"Invalid")) -> Valid | Q7: =IF(TRIM(G7)="","Missing",IFERROR(IF(AND(ISNUMBER(--TRIM(G7)),LEN(TRIM(G7))>=9,LEN(TRIM(G7))<=18,ISERROR(FIND(".",G7))),"Valid","Invalid"),"Invalid")) -> Valid | R7: =IF(TRIM(H7)="","Missing",IF(AND(LEN(TRIM(H7))=11,SUMPRODUCT(--(CODE(MID(TRIM(H7),{1,2,3,4},1))>=65),--(CODE(MID(TRIM(H7),{1,2,3,4},1))<=90))=4,MID(TRIM(H7),5,1)="0"),"Valid","Invalid")) -> Valid | S7: =IF(TRIM(I7)="","Missing",IF(EXACT(TRIM(I7),"India"),"Valid","Invalid")) -> Invalid | T7: =IF(TRIM(J7)="","Missing",IF(OR(EXACT(TRIM(J7),"Net 15"),EXACT(TRIM(J7),"Net 30"),EXACT(TRIM(J7),"Net 45"),EXACT(TRIM(J7),"Net 60")),"Valid","Invalid")) -> Valid | U7: =COUNTIF(M7:T7,"<>Valid") -> 1 | V7: =SUBSTITUTE(SUBSTITUTE(SUBSTITUTE(F7," ",""),"-",""),"+","") -> 919724004991 | W7: V1047 | X7: =IF(COUNTIF($W$2:$W$229,W7)>1,"Duplicate","Unique") -> Unique
A8: V1180 | B8: Bluewave Water Solutions Limited | C8: KOVCH2788C | D8: 33KOVCH2788C1Z3 | E8: accounts@bluewavewatersolutions.in | F8: +91 67422 43864 | G8: 81081866179 | H8: SBIN0549180 | I8: India | J8: 15 Days | K8: Active | L8: 2024-03-10 | M8: =IF(TRIM(C8)="","Missing",IF(AND(LEN(TRIM(C8))=10,SUMPRODUCT(--(CODE(MID(TRIM(C8),{1,2,3,4,5,10},1))>=65),--(CODE(MID(TRIM(C8),{1,2,3,4,5,10},1))<=90))=6,ISNUMBER(--MID(TRIM(C8),6,4))),"Valid","Invalid")) -> Valid | N8: =IF(TRIM(D8)="","Missing",IF(AND(LEN(TRIM(D8))=15,MID(TRIM(D8),14,1)="Z"),IF(AND(TRIM(C8)<>"",MID(TRIM(D8),3,10)=TRIM(C8)),"Valid","PAN Mismatch"),"Invalid")) -> Valid | O8: =IF(TRIM(E8)="","Missing",IF(AND(ISNUMBER(FIND("@",E8)),ISERROR(FIND(" ",TRIM(E8))),IFERROR(FIND(".",E8,FIND("@",E8)),0)>0),"Valid","Invalid")) -> Valid | P8: =IF(TRIM(F8)="","Missing",IFERROR(IF(AND(ISNUMBER(--V8),OR(LEN(V8)=10,AND(LEN(V8)=12,LEFT(V8,2)="91")),VALUE(LEFT(RIGHT(V8,10),1))>=6),"Valid","Invalid"),"Invalid")) -> Valid | Q8: =IF(TRIM(G8)="","Missing",IFERROR(IF(AND(ISNUMBER(--TRIM(G8)),LEN(TRIM(G8))>=9,LEN(TRIM(G8))<=18,ISERROR(FIND(".",G8))),"Valid","Invalid"),"Invalid")) -> Valid | R8: =IF(TRIM(H8)="","Missing",IF(AND(LEN(TRIM(H8))=11,SUMPRODUCT(--(CODE(MID(TRIM(H8),{1,2,3,4},1))>=65),--(CODE(MID(TRIM(H8),{1,2,3,4},1))<=90))=4,MID(TRIM(H8),5,1)="0"),"Valid","Invalid")) -> Valid | S8: =IF(TRIM(I8)="","Missing",IF(EXACT(TRIM(I8),"India"),"Valid","Invalid")) -> Valid | T8: =IF(TRIM(J8)="","Missing",IF(OR(EXACT(TRIM(J8),"Net 15"),EXACT(TRIM(J8),"Net 30"),EXACT(TRIM(J8),"Net 45"),EXACT(TRIM(J8),"Net 60")),"Valid","Invalid")) -> Invalid | U8: =COUNTIF(M8:T8,"<>Valid") -> 1 | V8: =SUBSTITUTE(SUBSTITUTE(SUBSTITUTE(F8," ",""),"-",""),"+","") -> 916742243864 | W8: V1180 | X8: =IF(COUNTIF($W$2:$W$229,W8)>1,"Duplicate","Unique") -> Unique
A9: V1186 | B9: Titan Stationers Private Limited | C9: NZHCE6667Q | D9: 19NZHCE6667Q1ZX | E9: accounts@titanstationers.in | F9: +91 92081 15562 | G9: 06029084668455 | H9: HDFC0489267 | I9: INDIA | J9: 30 Days | K9: Active | L9: 2023-12-17 | M9: =IF(TRIM(C9)="","Missing",IF(AND(LEN(TRIM(C9))=10,SUMPRODUCT(--(CODE(MID(TRIM(C9),{1,2,3,4,5,10},1))>=65),--(CODE(MID(TRIM(C9),{1,2,3,4,5,10},1))<=90))=6,ISNUMBER(--MID(TRIM(C9),6,4))),"Valid","Invalid")) -> Valid | N9: =IF(TRIM(D9)="","Missing",IF(AND(LEN(TRIM(D9))=15,MID(TRIM(D9),14,1)="Z"),IF(AND(TRIM(C9)<>"",MID(TRIM(D9),3,10)=TRIM(C9)),"Valid","PAN Mismatch"),"Invalid")) -> Valid | O9: =IF(TRIM(E9)="","Missing",IF(AND(ISNUMBER(FIND("@",E9)),ISERROR(FIND(" ",TRIM(E9))),IFERROR(FIND(".",E9,FIND("@",E9)),0)>0),"Valid","Invalid")) -> Valid | P9: =IF(TRIM(F9)="","Missing",IFERROR(IF(AND(ISNUMBER(--V9),OR(LEN(V9)=10,AND(LEN(V9)=12,LEFT(V9,2)="91")),VALUE(LEFT(RIGHT(V9,10),1))>=6),"Valid","Invalid"),"Invalid")) -> Valid | Q9: =IF(TRIM(G9)="","Missing",IFERROR(IF(AND(ISNUMBER(--TRIM(G9)),LEN(TRIM(G9))>=9,LEN(TRIM(G9))<=18,ISERROR(FIND(".",G9))),"Valid","Invalid"),"Invalid")) -> Valid | R9: =IF(TRIM(H9)="","Missing",IF(AND(LEN(TRIM(H9))=11,SUMPRODUCT(--(CODE(MID(TRIM(H9),{1,2,3,4},1))>=65),--(CODE(MID(TRIM(H9),{1,2,3,4},1))<=90))=4,MID(TRIM(H9),5,1)="0"),"Valid","Invalid")) -> Valid | S9: =IF(TRIM(I9)="","Missing",IF(EXACT(TRIM(I9),"India"),"Valid","Invalid")) -> Invalid | T9: =IF(TRIM(J9)="","Missing",IF(OR(EXACT(TRIM(J9),"Net 15"),EXACT(TRIM(J9),"Net 30"),EXACT(TRIM(J9),"Net 45"),EXACT(TRIM(J9),"Net 60")),"Valid","Invalid")) -> Invalid | U9: =COUNTIF(M9:T9,"<>Valid") -> 2 | V9: =SUBSTITUTE(SUBSTITUTE(SUBSTITUTE(F9," ",""),"-",""),"+","") -> 919208115562 | W9: V1186 | X9: =IF(COUNTIF($W$2:$W$229,W9)>1,"Duplicate","Unique") -> Unique
A10: V1108 | B10: Western Water Solutions Private Limited | C10: ZCECP9611I | D10: 29ZCECP9611I1ZX | E10: accounts@westernwatersolutions.in | F10: 6669849027 | G10: 03843098839205 | H10: ICIC0021465 | I10: INDIA | J10: 60 Days | K10: Active | L10: 2021-03-31 | M10: =IF(TRIM(C10)="","Missing",IF(AND(LEN(TRIM(C10))=10,SUMPRODUCT(--(CODE(MID(TRIM(C10),{1,2,3,4,5,10},1))>=65),--(CODE(MID(TRIM(C10),{1,2,3,4,5,10},1))<=90))=6,ISNUMBER(--MID(TRIM(C10),6,4))),"Valid","Invalid")) -> Valid | N10: =IF(TRIM(D10)="","Missing",IF(AND(LEN(TRIM(D10))=15,MID(TRIM(D10),14,1)="Z"),IF(AND(TRIM(C10)<>"",MID(TRIM(D10),3,10)=TRIM(C10)),"Valid","PAN Mismatch"),"Invalid")) -> Valid | O10: =IF(TRIM(E10)="","Missing",IF(AND(ISNUMBER(FIND("@",E10)),ISERROR(FIND(" ",TRIM(E10))),IFERROR(FIND(".",E10,FIND("@",E10)),0)>0),"Valid","Invalid")) -> Valid | P10: =IF(TRIM(F10)="","Missing",IFERROR(IF(AND(ISNUMBER(--V10),OR(LEN(V10)=10,AND(LEN(V10)=12,LEFT(V10,2)="91")),VALUE(LEFT(RIGHT(V10,10),1))>=6),"Valid","Invalid"),"Invalid")) -> Valid | Q10: =IF(TRIM(G10)="","Missing",IFERROR(IF(AND(ISNUMBER(--TRIM(G10)),LEN(TRIM(G10))>=9,LEN(TRIM(G10))<=18,ISERROR(FIND(".",G10))),"Valid","Invalid"),"Invalid")) -> Valid | R10: =IF(TRIM(H10)="","Missing",IF(AND(LEN(TRIM(H10))=11,SUMPRODUCT(--(CODE(MID(TRIM(H10),{1,2,3,4},1))>=65),--(CODE(MID(TRIM(H10),{1,2,3,4},1))<=90))=4,MID(TRIM(H10),5,1)="0"),"Valid","Invalid")) -> Valid | S10: =IF(TRIM(I10)="","Missing",IF(EXACT(TRIM(I10),"India"),"Valid","Invalid")) -> Invalid | T10: =IF(TRIM(J10)="","Missing",IF(OR(EXACT(TRIM(J10),"Net 15"),EXACT(TRIM(J10),"Net 30"),EXACT(TRIM(J10),"Net 45"),EXACT(TRIM(J10),"Net 60")),"Valid","Invalid")) -> Invalid | U10: =COUNTIF(M10:T10,"<>Valid") -> 2 | V10: =SUBSTITUTE(SUBSTITUTE(SUBSTITUTE(F10," ",""),"-",""),"+","") -> 6669849027 | W10: V1108 | X10: =IF(COUNTIF($W$2:$W$229,W10)>1,"Duplicate","Unique") -> Unique
A11: V1022 | B11: Sunrise Printing Pvt Ltd | C11: AVMCI0909X | D11: 07AVMCI0909X1ZS | E11: accounts@sunriseprinting | F11: 83394-21047 | G11: 95214562328 | H11: sbin0884247 | I11: India | J11: NET45 | K11: Active | L11: 2022-10-19 | M11: =IF(TRIM(C11)="","Missing",IF(AND(LEN(TRIM(C11))=10,SUMPRODUCT(--(CODE(MID(TRIM(C11),{1,2,3,4,5,10},1))>=65),--(CODE(MID(TRIM(C11),{1,2,3,4,5,10},1))<=90))=6,ISNUMBER(--MID(TRIM(C11),6,4))),"Valid","Invalid")) -> Valid | N11: =IF(TRIM(D11)="","Missing",IF(AND(LEN(TRIM(D11))=15,MID(TRIM(D11),14,1)="Z"),IF(AND(TRIM(C11)<>"",MID(TRIM(D11),3,10)=TRIM(C11)),"Valid","PAN Mismatch"),"Invalid")) -> Valid | O11: =IF(TRIM(E11)="","Missing",IF(AND(ISNUMBER(FIND("@",E11)),ISERROR(FIND(" ",TRIM(E11))),IFERROR(FIND(".",E11,FIND("@",E11)),0)>0),"Valid","Invalid")) -> Invalid | P11: =IF(TRIM(F11)="","Missing",IFERROR(IF(AND(ISNUMBER(--V11),OR(LEN(V11)=10,AND(LEN(V11)=12,LEFT(V11,2)="91")),VALUE(LEFT(RIGHT(V11,10),1))>=6),"Valid","Invalid"),"Invalid")) -> Valid | Q11: =IF(TRIM(G11)="","Missing",IFERROR(IF(AND(ISNUMBER(--TRIM(G11)),LEN(TRIM(G11))>=9,LEN(TRIM(G11))<=18,ISERROR(FIND(".",G11))),"Valid","Invalid"),"Invalid")) -> Valid | R11: =IF(TRIM(H11)="","Missing",IF(AND(LEN(TRIM(H11))=11,SUMPRODUCT(--(CODE(MID(TRIM(H11),{1,2,3,4},1))>=65),--(CODE(MID(TRIM(H11),{1,2,3,4},1))<=90))=4,MID(TRIM(H11),5,1)="0"),"Valid","Invalid")) -> Invalid | S11: =IF(TRIM(I11)="","Missing",IF(EXACT(TRIM(I11),"India"),"Valid","Invalid")) -> Valid | T11: =IF(TRIM(J11)="","Missing",IF(OR(EXACT(TRIM(J11),"Net 15"),EXACT(TRIM(J11),"Net 30"),EXACT(TRIM(J11),"Net 45"),EXACT(TRIM(J11),"Net 60")),"Valid","Invalid")) -> Invalid | U11: =COUNTIF(M11:T11,"<>Valid") -> 3 | V11: =SUBSTITUTE(SUBSTITUTE(SUBSTITUTE(F11," ",""),"-",""),"+","") -> 8339421047 | W11: V1022 | X11: =IF(COUNTIF($W$2:$W$229,W11)>1,"Duplicate","Unique") -> Unique
A12: V1083 | B12: Jupiter Maintenance Limited | C12: TTVCW6065W | D12: 29TTVCW6065W1ZD | E12: accounts@jupitermaintenance.in | F12: 85054-44713 | G12: 475469137367 | H12: KKBK0508214 | I12: India | J12: Net 60 | K12: Active | L12: 2024-11-17 | M12: =IF(TRIM(C12)="","Missing",IF(AND(LEN(TRIM(C12))=10,SUMPRODUCT(--(CODE(MID(TRIM(C12),{1,2,3,4,5,10},1))>=65),--(CODE(MID(TRIM(C12),{1,2,3,4,5,10},1))<=90))=6,ISNUMBER(--MID(TRIM(C12),6,4))),"Valid","Invalid")) -> Valid | N12: =IF(TRIM(D12)="","Missing",IF(AND(LEN(TRIM(D12))=15,MID(TRIM(D12),14,1)="Z"),IF(AND(TRIM(C12)<>"",MID(TRIM(D12),3,10)=TRIM(C12)),"Valid","PAN Mismatch"),"Invalid")) -> Valid | O12: =IF(TRIM(E12)="","Missing",IF(AND(ISNUMBER(FIND("@",E12)),ISERROR(FIND(" ",TRIM(E12))),IFERROR(FIND(".",E12,FIND("@",E12)),0)>0),"Valid","Invalid")) -> Valid | P12: =IF(TRIM(F12)="","Missing",IFERROR(IF(AND(ISNUMBER(--V12),OR(LEN(V12)=10,AND(LEN(V12)=12,LEFT(V12,2)="91")),VALUE(LEFT(RIGHT(V12,10),1))>=6),"Valid","Invalid"),"Invalid")) -> Valid | Q12: =IF(TRIM(G12)="","Missing",IFERROR(IF(AND(ISNUMBER(--TRIM(G12)),LEN(TRIM(G12))>=9,LEN(TRIM(G12))<=18,ISERROR(FIND(".",G12))),"Valid","Invalid"),"Invalid")) -> Valid | R12: =IF(TRIM(H12)="","Missing",IF(AND(LEN(TRIM(H12))=11,SUMPRODUCT(--(CODE(MID(TRIM(H12),{1,2,3,4},1))>=65),--(CODE(MID(TRIM(H12),{1,2,3,4},1))<=90))=4,MID(TRIM(H12),5,1)="0"),"Valid","Invalid")) -> Valid | S12: =IF(TRIM(I12)="","Missing",IF(EXACT(TRIM(I12),"India"),"Valid","Invalid")) -> Valid | T12: =IF(TRIM(J12)="","Missing",IF(OR(EXACT(TRIM(J12),"Net 15"),EXACT(TRIM(J12),"Net 30"),EXACT(TRIM(J12),"Net 45"),EXACT(TRIM(J12),"Net 60")),"Valid","Invalid")) -> Valid | U12: =COUNTIF(M12:T12,"<>Valid") -> 0 | V12: =SUBSTITUTE(SUBSTITUTE(SUBSTITUTE(F12," ",""),"-",""),"+","") -> 8505444713 | W12: V1083 | X12: =IF(COUNTIF($W$2:$W$229,W12)>1,"Duplicate","Unique") -> Unique
A13: V1051 | B13: Western Electricals Pvt Ltd | C13: OLECI3106T | E13: accounts@westernelectricals.in | F13: +91 71190 79030 | G13: 73830284395995 | H13: ICIC0428364 | I13: India | J13: net 45 | K13: Inactive | L13: 2020-12-18 | M13: =IF(TRIM(C13)="","Missing",IF(AND(LEN(TRIM(C13))=10,SUMPRODUCT(--(CODE(MID(TRIM(C13),{1,2,3,4,5,10},1))>=65),--(CODE(MID(TRIM(C13),{1,2,3,4,5,10},1))<=90))=6,ISNUMBER(--MID(TRIM(C13),6,4))),"Valid","Invalid")) -> Valid | N13: =IF(TRIM(D13)="","Missing",IF(AND(LEN(TRIM(D13))=15,MID(TRIM(D13),14,1)="Z"),IF(AND(TRIM(C13)<>"",MID(TRIM(D13),3,10)=TRIM(C13)),"Valid","PAN Mismatch"),"Invalid")) -> Missing | O13: =IF(TRIM(E13)="","Missing",IF(AND(ISNUMBER(FIND("@",E13)),ISERROR(FIND(" ",TRIM(E13))),IFERROR(FIND(".",E13,FIND("@",E13)),0)>0),"Valid","Invalid")) -> Valid | P13: =IF(TRIM(F13)="","Missing",IFERROR(IF(AND(ISNUMBER(--V13),OR(LEN(V13)=10,AND(LEN(V13)=12,LEFT(V13,2)="91")),VALUE(LEFT(RIGHT(V13,10),1))>=6),"Valid","Invalid"),"Invalid")) -> Valid | Q13: =IF(TRIM(G13)="","Missing",IFERROR(IF(AND(ISNUMBER(--TRIM(G13)),LEN(TRIM(G13))>=9,LEN(TRIM(G13))<=18,ISERROR(FIND(".",G13))),"Valid","Invalid"),"Invalid")) -> Valid | R13: =IF(TRIM(H13)="","Missing",IF(AND(LEN(TRIM(H13))=11,SUMPRODUCT(--(CODE(MID(TRIM(H13),{1,2,3,4},1))>=65),--(CODE(MID(TRIM(H13),{1,2,3,4},1))<=90))=4,MID(TRIM(H13),5,1)="0"),"Valid","Invalid")) -> Valid | S13: =IF(TRIM(I13)="","Missing",IF(EXACT(TRIM(I13),"India"),"Valid","Invalid")) -> Valid | T13: =IF(TRIM(J13)="","Missing",IF(OR(EXACT(TRIM(J13),"Net 15"),EXACT(TRIM(J13),"Net 30"),EXACT(TRIM(J13),"Net 45"),EXACT(TRIM(J13),"Net 60")),"Valid","Invalid")) -> Invalid | U13: =COUNTIF(M13:T13,"<>Valid") -> 2 | V13: =SUBSTITUTE(SUBSTITUTE(SUBSTITUTE(F13," ",""),"-",""),"+","") -> 917119079030 | W13: V1203 | X13: =IF(COUNTIF($W$2:$W$229,W13)>1,"Duplicate","Unique") -> Duplicate
A14: V1179 | B14: Bluewave Printing Pvt Ltd | C14: TMCCM4236C | D14: 27TMCCM4236C1ZN | E14: ACCOUNTS@BLUEWAVEPRINTING.IN | F14: +91 96421 47649 | G14: 515837767499 | H14: UTIB0165926 | I14: india | J14: 60D | K14: Inactive | L14: 2024-10-03 | M14: =IF(TRIM(C14)="","Missing",IF(AND(LEN(TRIM(C14))=10,SUMPRODUCT(--(CODE(MID(TRIM(C14),{1,2,3,4,5,10},1))>=65),--(CODE(MID(TRIM(C14),{1,2,3,4,5,10},1))<=90))=6,ISNUMBER(--MID(TRIM(C14),6,4))),"Valid","Invalid")) -> Valid | N14: =IF(TRIM(D14)="","Missing",IF(AND(LEN(TRIM(D14))=15,MID(TRIM(D14),14,1)="Z"),IF(AND(TRIM(C14)<>"",MID(TRIM(D14),3,10)=TRIM(C14)),"Valid","PAN Mismatch"),"Invalid")) -> Valid | O14: =IF(TRIM(E14)="","Missing",IF(AND(ISNUMBER(FIND("@",E14)),ISERROR(FIND(" ",TRIM(E14))),IFERROR(FIND(".",E14,FIND("@",E14)),0)>0),"Valid","Invalid")) -> Valid | P14: =IF(TRIM(F14)="","Missing",IFERROR(IF(AND(ISNUMBER(--V14),OR(LEN(V14)=10,AND(LEN(V14)=12,LEFT(V14,2)="91")),VALUE(LEFT(RIGHT(V14,10),1))>=6),"Valid","Invalid"),"Invalid")) -> Valid | Q14: =IF(TRIM(G14)="","Missing",IFERROR(IF(AND(ISNUMBER(--TRIM(G14)),LEN(TRIM(G14))>=9,LEN(TRIM(G14))<=18,ISERROR(FIND(".",G14))),"Valid","Invalid"),"Invalid")) -> Valid | R14: =IF(TRIM(H14)="","Missing",IF(AND(LEN(TRIM(H14))=11,SUMPRODUCT(--(CODE(MID(TRIM(H14),{1,2,3,4},1))>=65),--(CODE(MID(TRIM(H14),{1,2,3,4},1))<=90))=4,MID(TRIM(H14),5,1)="0"),"Valid","Invalid")) -> Valid | S14: =IF(TRIM(I14)="","Missing",IF(EXACT(TRIM(I14),"India"),"Valid","Invalid")) -> Invalid | T14: =IF(TRIM(J14)="","Missing",IF(OR(EXACT(TRIM(J14),"Net 15"),EXACT(TRIM(J14),"Net 30"),EXACT(TRIM(J14),"Net 45"),EXACT(TRIM(J14),"Net 60")),"Valid","Invalid")) -> Invalid | U14: =COUNTIF(M14:T14,"<>Valid") -> 2 | V14: =SUBSTITUTE(SUBSTITUTE(SUBSTITUTE(F14," ",""),"-",""),"+","") -> 919642147649 | W14: V1179 | X14: =IF(COUNTIF($W$2:$W$229,W14)>1,"Duplicate","Unique") -> Unique
A15: V1073 | B15: Delta IT Services Limited | C15: CSSCB6234I | D15: 19CSSCB6234I1ZU | E15: accounts@deltaitservices.in | F15: +91 85743 13291 | G15: 127756185374 | H15: UTIB0411249 | I15: India | J15: 15D | K15: Active | L15: 2022-09-04 | M15: =IF(TRIM(C15)="","Missing",IF(AND(LEN(TRIM(C15))=10,SUMPRODUCT(--(CODE(MID(TRIM(C15),{1,2,3,4,5,10},1))>=65),--(CODE(MID(TRIM(C15),{1,2,3,4,5,10},1))<=90))=6,ISNUMBER(--MID(TRIM(C15),6,4))),"Valid","Invalid")) -> Valid | N15: =IF(TRIM(D15)="","Missing",IF(AND(LEN(TRIM(D15))=15,MID(TRIM(D15),14,1)="Z"),IF(AND(TRIM(C15)<>"",MID(TRIM(D15),3,10)=TRIM(C15)),"Valid","PAN Mismatch"),"Invalid")) -> Valid | O15: =IF(TRIM(E15)="","Missing",IF(AND(ISNUMBER(FIND("@",E15)),ISERROR(FIND(" ",TRIM(E15))),IFERROR(FIND(".",E15,FIND("@",E15)),0)>0),"Valid","Invalid")) -> Valid | P15: =IF(TRIM(F15)="","Missing",IFERROR(IF(AND(ISNUMBER(--V15),OR(LEN(V15)=10,AND(LEN(V15)=12,LEFT(V15,2)="91")),VALUE(LEFT(RIGHT(V15,10),1))>=6),"Valid","Invalid"),"Invalid")) -> Valid | Q15: =IF(TRIM(G15)="","Missing",IFERROR(IF(AND(ISNUMBER(--TRIM(G15)),LEN(TRIM(G15))>=9,LEN(TRIM(G15))<=18,ISERROR(FIND(".",G15))),"Valid","Invalid"),"Invalid")) -> Valid | R15: =IF(TRIM(H15)="","Missing",IF(AND(LEN(TRIM(H15))=11,SUMPRODUCT(--(CODE(MID(TRIM(H15),{1,2,3,4},1))>=65),--(CODE(MID(TRIM(H15),{1,2,3,4},1))<=90))=4,MID(TRIM(H15),5,1)="0"),"Valid","Invalid")) -> Valid | S15: =IF(TRIM(I15)="","Missing",IF(EXACT(TRIM(I15),"India"),"Valid","Invalid")) -> Valid | T15: =IF(TRIM(J15)="","Missing",IF(OR(EXACT(TRIM(J15),"Net 15"),EXACT(TRIM(J15),"Net 30"),EXACT(TRIM(J15),"Net 45"),EXACT(TRIM(J15),"Net 60")),"Valid","Invalid")) -> Invalid | U15: =COUNTIF(M15:T15,"<>Valid") -> 1 | V15: =SUBSTITUTE(SUBSTITUTE(SUBSTITUTE(F15," ",""),"-",""),"+","") -> 918574313291 | W15: V1073 | X15: =IF(COUNTIF($W$2:$W$229,W15)>1,"Duplicate","Unique") -> Unique
A16: V1131 | B16: Falcon Power Systems Private Limited | C16: OSWCG7145W | D16: 36OSWCG7145W1ZK | E16: ACCOUNTS@FALCONPOWERSYSTEMS.IN | F16: +91 61751 86892 | G16: 86025922220644 | H16: UTIB0421230 | I16: IN | J16: Net 45 | K16: Inactive | L16: 2024-07-31 | M16: =IF(TRIM(C16)="","Missing",IF(AND(LEN(TRIM(C16))=10,SUMPRODUCT(--(CODE(MID(TRIM(C16),{1,2,3,4,5,10},1))>=65),--(CODE(MID(TRIM(C16),{1,2,3,4,5,10},1))<=90))=6,ISNUMBER(--MID(TRIM(C16),6,4))),"Valid","Invalid")) -> Valid | N16: =IF(TRIM(D16)="","Missing",IF(AND(LEN(TRIM(D16))=15,MID(TRIM(D16),14,1)="Z"),IF(AND(TRIM(C16)<>"",MID(TRIM(D16),3,10)=TRIM(C16)),"Valid","PAN Mismatch"),"Invalid")) -> Valid | O16: =IF(TRIM(E16)="","Missing",IF(AND(ISNUMBER(FIND("@",E16)),ISERROR(FIND(" ",TRIM(E16))),IFERROR(FIND(".",E16,FIND("@",E16)),0)>0),"Valid","Invalid")) -> Valid | P16: =IF(TRIM(F16)="","Missing",IFERROR(IF(AND(ISNUMBER(--V16),OR(LEN(V16)=10,AND(LEN(V16)=12,LEFT(V16,2)="91")),VALUE(LEFT(RIGHT(V16,10),1))>=6),"Valid","Invalid"),"Invalid")) -> Valid | Q16: =IF(TRIM(G16)="","Missing",IFERROR(IF(AND(ISNUMBER(--TRIM(G16)),LEN(TRIM(G16))>=9,LEN(TRIM(G16))<=18,ISERROR(FIND(".",G16))),"Valid","Invalid"),"Invalid")) -> Valid | R16: =IF(TRIM(H16)="","Missing",IF(AND(LEN(TRIM(H16))=11,SUMPRODUCT(--(CODE(MID(TRIM(H16),{1,2,3,4},1))>=65),--(CODE(MID(TRIM(H16),{1,2,3,4},1))<=90))=4,MID(TRIM(H16),5,1)="0"),"Valid","Invalid")) -> Valid | S16: =IF(TRIM(I16)="","Missing",IF(EXACT(TRIM(I16),"India"),"Valid","Invalid")) -> Invalid | T16: =IF(TRIM(J16)="","Missing",IF(OR(EXACT(TRIM(J16),"Net 15"),EXACT(TRIM(J16),"Net 30"),EXACT(TRIM(J16),"Net 45"),EXACT(TRIM(J16),"Net 60")),"Valid","Invalid")) -> Valid | U16: =COUNTIF(M16:T16,"<>Valid") -> 1 | V16: =SUBSTITUTE(SUBSTITUTE(SUBSTITUTE(F16," ",""),"-",""),"+","") -> 916175186892 | W16: V1131 | X16: =IF(COUNTIF($W$2:$W$229,W16)>1,"Duplicate","Unique") -> Unique
A17: V1198 | B17: Western Engineering Works Limited | C17: MDTCY6399A | D17: 07MDTCY6399A1ZY | E17: ACCOUNTS@WESTERNENGINEERINGWORKS.IN | H17: UTIB0797232 | I17: India | J17: NET15 | K17: Inactive | L17: 2022-06-30 | M17: =IF(TRIM(C17)="","Missing",IF(AND(LEN(TRIM(C17))=10,SUMPRODUCT(--(CODE(MID(TRIM(C17),{1,2,3,4,5,10},1))>=65),--(CODE(MID(TRIM(C17),{1,2,3,4,5,10},1))<=90))=6,ISNUMBER(--MID(TRIM(C17),6,4))),"Valid","Invalid")) -> Valid | N17: =IF(TRIM(D17)="","Missing",IF(AND(LEN(TRIM(D17))=15,MID(TRIM(D17),14,1)="Z"),IF(AND(TRIM(C17)<>"",MID(TRIM(D17),3,10)=TRIM(C17)),"Valid","PAN Mismatch"),"Invalid")) -> Valid | O17: =IF(TRIM(E17)="","Missing",IF(AND(ISNUMBER(FIND("@",E17)),ISERROR(FIND(" ",TRIM(E17))),IFERROR(FIND(".",E17,FIND("@",E17)),0)>0),"Valid","Invalid")) -> Valid | P17: =IF(TRIM(F17)="","Missing",IFERROR(IF(AND(ISNUMBER(--V17),OR(LEN(V17)=10,AND(LEN(V17)=12,LEFT(V17,2)="91")),VALUE(LEFT(RIGHT(V17,10),1))>=6),"Valid","Invalid"),"Invalid")) -> Missing | Q17: =IF(TRIM(G17)="","Missing",IFERROR(IF(AND(ISNUMBER(--TRIM(G17)),LEN(TRIM(G17))>=9,LEN(TRIM(G17))<=18,ISERROR(FIND(".",G17))),"Valid","Invalid"),"Invalid")) -> Missing | R17: =IF(TRIM(H17)="","Missing",IF(AND(LEN(TRIM(H17))=11,SUMPRODUCT(--(CODE(MID(TRIM(H17),{1,2,3,4},1))>=65),--(CODE(MID(TRIM(H17),{1,2,3,4},1))<=90))=4,MID(TRIM(H17),5,1)="0"),"Valid","Invalid")) -> Valid | S17: =IF(TRIM(I17)="","Missing",IF(EXACT(TRIM(I17),"India"),"Valid","Invalid")) -> Valid | T17: =IF(TRIM(J17)="","Missing",IF(OR(EXACT(TRIM(J17),"Net 15"),EXACT(TRIM(J17),"Net 30"),EXACT(TRIM(J17),"Net 45"),EXACT(TRIM(J17),"Net 60")),"Valid","Invalid")) -> Invalid | U17: =COUNTIF(M17:T17,"<>Valid") -> 3 | V17: =SUBSTITUTE(SUBSTITUTE(SUBSTITUTE(F17," ",""),"-",""),"+","") | W17: V1198 | X17: =IF(COUNTIF($W$2:$W$229,W17)>1,"Duplicate","Unique") -> Unique
A18: V1161 | B18: Falcon Pest Control Limited | C18: SBECK7252B | D18: 33SBECK7252B1ZX | E18: ACCOUNTS@FALCONPESTCONTROL.IN | F18: 8044818321 | G18: 855445189520 | H18: ICIC0845765 | I18: India | J18: NET30 | K18: Active | L18: 2020-09-25 | M18: =IF(TRIM(C18)="","Missing",IF(AND(LEN(TRIM(C18))=10,SUMPRODUCT(--(CODE(MID(TRIM(C18),{1,2,3,4,5,10},1))>=65),--(CODE(MID(TRIM(C18),{1,2,3,4,5,10},1))<=90))=6,ISNUMBER(--MID(TRIM(C18),6,4))),"Valid","Invalid")) -> Valid | N18: =IF(TRIM(D18)="","Missing",IF(AND(LEN(TRIM(D18))=15,MID(TRIM(D18),14,1)="Z"),IF(AND(TRIM(C18)<>"",MID(TRIM(D18),3,10)=TRIM(C18)),"Valid","PAN Mismatch"),"Invalid")) -> Valid | O18: =IF(TRIM(E18)="","Missing",IF(AND(ISNUMBER(FIND("@",E18)),ISERROR(FIND(" ",TRIM(E18))),IFERROR(FIND(".",E18,FIND("@",E18)),0)>0),"Valid","Invalid")) -> Valid | P18: =IF(TRIM(F18)="","Missing",IFERROR(IF(AND(ISNUMBER(--V18),OR(LEN(V18)=10,AND(LEN(V18)=12,LEFT(V18,2)="91")),VALUE(LEFT(RIGHT(V18,10),1))>=6),"Valid","Invalid"),"Invalid")) -> Valid | Q18: =IF(TRIM(G18)="","Missing",IFERROR(IF(AND(ISNUMBER(--TRIM(G18)),LEN(TRIM(G18))>=9,LEN(TRIM(G18))<=18,ISERROR(FIND(".",G18))),"Valid","Invalid"),"Invalid")) -> Valid | R18: =IF(TRIM(H18)="","Missing",IF(AND(LEN(TRIM(H18))=11,SUMPRODUCT(--(CODE(MID(TRIM(H18),{1,2,3,4},1))>=65),--(CODE(MID(TRIM(H18),{1,2,3,4},1))<=90))=4,MID(TRIM(H18),5,1)="0"),"Valid","Invalid")) -> Valid | S18: =IF(TRIM(I18)="","Missing",IF(EXACT(TRIM(I18),"India"),"Valid","Invalid")) -> Valid | T18: =IF(TRIM(J18)="","Missing",IF(OR(EXACT(TRIM(J18),"Net 15"),EXACT(TRIM(J18),"Net 30"),EXACT(TRIM(J18),"Net 45"),EXACT(TRIM(J18),"Net 60")),"Valid","Invalid")) -> Invalid | U18: =COUNTIF(M18:T18,"<>Valid") -> 1 | V18: =SUBSTITUTE(SUBSTITUTE(SUBSTITUTE(F18," ",""),"-",""),"+","") -> 8044818321 | W18: V1161 | X18: =IF(COUNTIF($W$2:$W$229,W18)>1,"Duplicate","Unique") -> Unique
A19: V1010 | B19: Delta Maintenance Limited | C19: KROCN0366Y | D19: 24KROCN0366Y1ZB | E19: accounts@deltamaintenance.in | F19: +91 90546 68893 | G19: 34670656272980 | H19: UTIB0990162 | I19: India | J19: net 60 | K19: Active | L19: 2021-12-01 | M19: =IF(TRIM(C19)="","Missing",IF(AND(LEN(TRIM(C19))=10,SUMPRODUCT(--(CODE(MID(TRIM(C19),{1,2,3,4,5,10},1))>=65),--(CODE(MID(TRIM(C19),{1,2,3,4,5,10},1))<=90))=6,ISNUMBER(--MID(TRIM(C19),6,4))),"Valid","Invalid")) -> Valid | N19: =IF(TRIM(D19)="","Missing",IF(AND(LEN(TRIM(D19))=15,MID(TRIM(D19),14,1)="Z"),IF(AND(TRIM(C19)<>"",MID(TRIM(D19),3,10)=TRIM(C19)),"Valid","PAN Mismatch"),"Invalid")) -> Valid | O19: =IF(TRIM(E19)="","Missing",IF(AND(ISNUMBER(FIND("@",E19)),ISERROR(FIND(" ",TRIM(E19))),IFERROR(FIND(".",E19,FIND("@",E19)),0)>0),"Valid","Invalid")) -> Valid | P19: =IF(TRIM(F19)="","Missing",IFERROR(IF(AND(ISNUMBER(--V19),OR(LEN(V19)=10,AND(LEN(V19)=12,LEFT(V19,2)="91")),VALUE(LEFT(RIGHT(V19,10),1))>=6),"Valid","Invalid"),"Invalid")) -> Valid | Q19: =IF(TRIM(G19)="","Missing",IFERROR(IF(AND(ISNUMBER(--TRIM(G19)),LEN(TRIM(G19))>=9,LEN(TRIM(G19))<=18,ISERROR(FIND(".",G19))),"Valid","Invalid"),"Invalid")) -> Valid | R19: =IF(TRIM(H19)="","Missing",IF(AND(LEN(TRIM(H19))=11,SUMPRODUCT(--(CODE(MID(TRIM(H19),{1,2,3,4},1))>=65),--(CODE(MID(TRIM(H19),{1,2,3,4},1))<=90))=4,MID(TRIM(H19),5,1)="0"),"Valid","Invalid")) -> Valid | S19: =IF(TRIM(I19)="","Missing",IF(EXACT(TRIM(I19),"India"),"Valid","Invalid")) -> Valid | T19: =IF(TRIM(J19)="","Missing",IF(OR(EXACT(TRIM(J19),"Net 15"),EXACT(TRIM(J19),"Net 30"),EXACT(TRIM(J19),"Net 45"),EXACT(TRIM(J19),"Net 60")),"Valid","Invalid")) -> Invalid | U19: =COUNTIF(M19:T19,"<>Valid") -> 1 | V19: =SUBSTITUTE(SUBSTITUTE(SUBSTITUTE(F19," ",""),"-",""),"+","") -> 919054668893 | W19: V1010 | X19: =IF(COUNTIF($W$2:$W$229,W19)>1,"Duplicate","Unique") -> Unique
A20: V1104 | B20: Crestline Logistics LLP | C20: PZPCT0827F | D20: 29PGCQQ0827F1ZE | E20: accounts@crestlinelogistics.in | F20: +91 72225 91365 | G20: 77739260302 | I20: IN | J20: NET30 | K20: Inactive | L20: 2021-11-23 | M20: =IF(TRIM(C20)="","Missing",IF(AND(LEN(TRIM(C20))=10,SUMPRODUCT(--(CODE(MID(TRIM(C20),{1,2,3,4,5,10},1))>=65),--(CODE(MID(TRIM(C20),{1,2,3,4,5,10},1))<=90))=6,ISNUMBER(--MID(TRIM(C20),6,4))),"Valid","Invalid")) -> Valid | N20: =IF(TRIM(D20)="","Missing",IF(AND(LEN(TRIM(D20))=15,MID(TRIM(D20),14,1)="Z"),IF(AND(TRIM(C20)<>"",MID(TRIM(D20),3,10)=TRIM(C20)),"Valid","PAN Mismatch"),"Invalid")) -> PAN Mismatch | O20: =IF(TRIM(E20)="","Missing",IF(AND(ISNUMBER(FIND("@",E20)),ISERROR(FIND(" ",TRIM(E20))),IFERROR(FIND(".",E20,FIND("@",E20)),0)>0),"Valid","Invalid")) -> Valid | P20: =IF(TRIM(F20)="","Missing",IFERROR(IF(AND(ISNUMBER(--V20),OR(LEN(V20)=10,AND(LEN(V20)=12,LEFT(V20,2)="91")),VALUE(LEFT(RIGHT(V20,10),1))>=6),"Valid","Invalid"),"Invalid")) -> Valid | Q20: =IF(TRIM(G20)="","Missing",IFERROR(IF(AND(ISNUMBER(--TRIM(G20)),LEN(TRIM(G20))>=9,LEN(TRIM(G20))<=18,ISERROR(FIND(".",G20))),"Valid","Invalid"),"Invalid")) -> Valid | R20: =IF(TRIM(H20)="","Missing",IF(AND(LEN(TRIM(H20))=11,SUMPRODUCT(--(CODE(MID(TRIM(H20),{1,2,3,4},1))>=65),--(CODE(MID(TRIM(H20),{1,2,3,4},1))<=90))=4,MID(TRIM(H20),5,1)="0"),"Valid","Invalid")) -> Missing | S20: =IF(TRIM(I20)="","Missing",IF(EXACT(TRIM(I20),"India"),"Valid","Invalid")) -> Invalid | T20: =IF(TRIM(J20)="","Missing",IF(OR(EXACT(TRIM(J20),"Net 15"),EXACT(TRIM(J20),"Net 30"),EXACT(TRIM(J20),"Net 45"),EXACT(TRIM(J20),"Net 60")),"Valid","Invalid")) -> Invalid | U20: =COUNTIF(M20:T20,"<>Valid") -> 4 | V20: =SUBSTITUTE(SUBSTITUTE(SUBSTITUTE(F20," ",""),"-",""),"+","") -> 917222591365 | W20: V1104 | X20: =IF(COUNTIF($W$2:$W$229,W20)>1,"Duplicate","Unique") -> Unique
A21: V1199 | B21: Sunrise Landscaping Limited | C21: SNQCU5498Y | D21: 29SNQCU5498Y1ZJ | E21: ACCOUNTS@SUNRISELANDSCAPING.IN | F21: 8954508920 | G21: 880653331537 | H21: UTIB0959959 | I21: India | J21: Net 45 | K21: Active | L21: 2020-10-26 | M21: =IF(TRIM(C21)="","Missing",IF(AND(LEN(TRIM(C21))=10,SUMPRODUCT(--(CODE(MID(TRIM(C21),{1,2,3,4,5,10},1))>=65),--(CODE(MID(TRIM(C21),{1,2,3,4,5,10},1))<=90))=6,ISNUMBER(--MID(TRIM(C21),6,4))),"Valid","Invalid")) -> Valid | N21: =IF(TRIM(D21)="","Missing",IF(AND(LEN(TRIM(D21))=15,MID(TRIM(D21),14,1)="Z"),IF(AND(TRIM(C21)<>"",MID(TRIM(D21),3,10)=TRIM(C21)),"Valid","PAN Mismatch"),"Invalid")) -> Valid | O21: =IF(TRIM(E21)="","Missing",IF(AND(ISNUMBER(FIND("@",E21)),ISERROR(FIND(" ",TRIM(E21))),IFERROR(FIND(".",E21,FIND("@",E21)),0)>0),"Valid","Invalid")) -> Valid | P21: =IF(TRIM(F21)="","Missing",IFERROR(IF(AND(ISNUMBER(--V21),OR(LEN(V21)=10,AND(LEN(V21)=12,LEFT(V21,2)="91")),VALUE(LEFT(RIGHT(V21,10),1))>=6),"Valid","Invalid"),"Invalid")) -> Valid | Q21: =IF(TRIM(G21)="","Missing",IFERROR(IF(AND(ISNUMBER(--TRIM(G21)),LEN(TRIM(G21))>=9,LEN(TRIM(G21))<=18,ISERROR(FIND(".",G21))),"Valid","Invalid"),"Invalid")) -> Valid | R21: =IF(TRIM(H21)="","Missing",IF(AND(LEN(TRIM(H21))=11,SUMPRODUCT(--(CODE(MID(TRIM(H21),{1,2,3,4},1))>=65),--(CODE(MID(TRIM(H21),{1,2,3,4},1))<=90))=4,MID(TRIM(H21),5,1)="0"),"Valid","Invalid")) -> Valid | S21: =IF(TRIM(I21)="","Missing",IF(EXACT(TRIM(I21),"India"),"Valid","Invalid")) -> Valid | T21: =IF(TRIM(J21)="","Missing",IF(OR(EXACT(TRIM(J21),"Net 15"),EXACT(TRIM(J21),"Net 30"),EXACT(TRIM(J21),"Net 45"),EXACT(TRIM(J21),"Net 60")),"Valid","Invalid")) -> Valid | U21: =COUNTIF(M21:T21,"<>Valid") -> 0 | V21: =SUBSTITUTE(SUBSTITUTE(SUBSTITUTE(F21," ",""),"-",""),"+","") -> 8954508920 | W21: V1199 | X21: =IF(COUNTIF($W$2:$W$229,W21)>1,"Duplicate","Unique") -> Duplicate
A22: V1082 | B22: Horizon IT Services LLP | C22: GUECT4511M | D22: 24GUECT4511M1ZZ | E22: accounts@horizonitservices.in | F22: 88709-98616 | G22: 299911914856 | I22: INDIA | J22: NET30 | K22: Active | L22: 2020-08-12 | M22: =IF(TRIM(C22)="","Missing",IF(AND(LEN(TRIM(C22))=10,SUMPRODUCT(--(CODE(MID(TRIM(C22),{1,2,3,4,5,10},1))>=65),--(CODE(MID(TRIM(C22),{1,2,3,4,5,10},1))<=90))=6,ISNUMBER(--MID(TRIM(C22),6,4))),"Valid","Invalid")) -> Valid | N22: =IF(TRIM(D22)="","Missing",IF(AND(LEN(TRIM(D22))=15,MID(TRIM(D22),14,1)="Z"),IF(AND(TRIM(C22)<>"",MID(TRIM(D22),3,10)=TRIM(C22)),"Valid","PAN Mismatch"),"Invalid")) -> Valid | O22: =IF(TRIM(E22)="","Missing",IF(AND(ISNUMBER(FIND("@",E22)),ISERROR(FIND(" ",TRIM(E22))),IFERROR(FIND(".",E22,FIND("@",E22)),0)>0),"Valid","Invalid")) -> Valid | P22: =IF(TRIM(F22)="","Missing",IFERROR(IF(AND(ISNUMBER(--V22),OR(LEN(V22)=10,AND(LEN(V22)=12,LEFT(V22,2)="91")),VALUE(LEFT(RIGHT(V22,10),1))>=6),"Valid","Invalid"),"Invalid")) -> Valid | Q22: =IF(TRIM(G22)="","Missing",IFERROR(IF(AND(ISNUMBER(--TRIM(G22)),LEN(TRIM(G22))>=9,LEN(TRIM(G22))<=18,ISERROR(FIND(".",G22))),"Valid","Invalid"),"Invalid")) -> Valid | R22: =IF(TRIM(H22)="","Missing",IF(AND(LEN(TRIM(H22))=11,SUMPRODUCT(--(CODE(MID(TRIM(H22),{1,2,3,4},1))>=65),--(CODE(MID(TRIM(H22),{1,2,3,4},1))<=90))=4,MID(TRIM(H22),5,1)="0"),"Valid","Invalid")) -> Missing | S22: =IF(TRIM(I22)="","Missing",IF(EXACT(TRIM(I22),"India"),"Valid","Invalid")) -> Invalid | T22: =IF(TRIM(J22)="","Missing",IF(OR(EXACT(TRIM(J22),"Net 15"),EXACT(TRIM(J22),"Net 30"),EXACT(TRIM(J22),"Net 45"),EXACT(TRIM(J22),"Net 60")),"Valid","Invalid")) -> Invalid | U22: =COUNTIF(M22:T22,"<>Valid") -> 3 | V22: =SUBSTITUTE(SUBSTITUTE(SUBSTITUTE(F22," ",""),"-",""),"+","") -> 8870998616 | W22: V1082 | X22: =IF(COUNTIF($W$2:$W$229,W22)>1,"Duplicate","Unique") -> Unique
A23: V1024 | B23: Apex Landscaping Limited | C23: MOLCV8692N | D23: 36MOLCV8692N1ZG | E23: accounts@apexlandscaping.in | F23: 9405377351 | G23: 8506431713900 | H23: SBIN0329318 | I23: India | J23: net 30 | K23: Active | L23: 2021-08-12 | M23: =IF(TRIM(C23)="","Missing",IF(AND(LEN(TRIM(C23))=10,SUMPRODUCT(--(CODE(MID(TRIM(C23),{1,2,3,4,5,10},1))>=65),--(CODE(MID(TRIM(C23),{1,2,3,4,5,10},1))<=90))=6,ISNUMBER(--MID(TRIM(C23),6,4))),"Valid","Invalid")) -> Valid | N23: =IF(TRIM(D23)="","Missing",IF(AND(LEN(TRIM(D23))=15,MID(TRIM(D23),14,1)="Z"),IF(AND(TRIM(C23)<>"",MID(TRIM(D23),3,10)=TRIM(C23)),"Valid","PAN Mismatch"),"Invalid")) -> Valid | O23: =IF(TRIM(E23)="","Missing",IF(AND(ISNUMBER(FIND("@",E23)),ISERROR(FIND(" ",TRIM(E23))),IFERROR(FIND(".",E23,FIND("@",E23)),0)>0),"Valid","Invalid")) -> Valid | P23: =IF(TRIM(F23)="","Missing",IFERROR(IF(AND(ISNUMBER(--V23),OR(LEN(V23)=10,AND(LEN(V23)=12,LEFT(V23,2)="91")),VALUE(LEFT(RIGHT(V23,10),1))>=6),"Valid","Invalid"),"Invalid")) -> Valid | Q23: =IF(TRIM(G23)="","Missing",IFERROR(IF(AND(ISNUMBER(--TRIM(G23)),LEN(TRIM(G23))>=9,LEN(TRIM(G23))<=18,ISERROR(FIND(".",G23))),"Valid","Invalid"),"Invalid")) -> Valid | R23: =IF(TRIM(H23)="","Missing",IF(AND(LEN(TRIM(H23))=11,SUMPRODUCT(--(CODE(MID(TRIM(H23),{1,2,3,4},1))>=65),--(CODE(MID(TRIM(H23),{1,2,3,4},1))<=90))=4,MID(TRIM(H23),5,1)="0"),"Valid","Invalid")) -> Valid | S23: =IF(TRIM(I23)="","Missing",IF(EXACT(TRIM(I23),"India"),"Valid","Invalid")) -> Valid | T23: =IF(TRIM(J23)="","Missing",IF(OR(EXACT(TRIM(J23),"Net 15"),EXACT(TRIM(J23),"Net 30"),EXACT(TRIM(J23),"Net 45"),EXACT(TRIM(J23),"Net 60")),"Valid","Invalid")) -> Invalid | U23: =COUNTIF(M23:T23,"<>Valid") -> 1 | V23: =SUBSTITUTE(SUBSTITUTE(SUBSTITUTE(F23," ",""),"-",""),"+","") -> 9405377351 | W23: V1024 | X23: =IF(COUNTIF($W$2:$W$229,W23)>1,"Duplicate","Unique") -> Unique
A24: V1163 | B24: Lotus Stationers LLP | C24: BZVCQ9071I | E24: ACCOUNTS@LOTUSSTATIONERS.IN | F24: 61193-93250 | G24: 24955289389 | H24: HDFC0190833 | I24: India | J24: NET45 | K24: Active | L24: 2025-01-09 | M24: =IF(TRIM(C24)="","Missing",IF(AND(LEN(TRIM(C24))=10,SUMPRODUCT(--(CODE(MID(TRIM(C24),{1,2,3,4,5,10},1))>=65),--(CODE(MID(TRIM(C24),{1,2,3,4,5,10},1))<=90))=6,ISNUMBER(--MID(TRIM(C24),6,4))),"Valid","Invalid")) -> Valid | N24: =IF(TRIM(D24)="","Missing",IF(AND(LEN(TRIM(D24))=15,MID(TRIM(D24),14,1)="Z"),IF(AND(TRIM(C24)<>"",MID(TRIM(D24),3,10)=TRIM(C24)),"Valid","PAN Mismatch"),"Invalid")) -> Missing | O24: =IF(TRIM(E24)="","Missing",IF(AND(ISNUMBER(FIND("@",E24)),ISERROR(FIND(" ",TRIM(E24))),IFERROR(FIND(".",E24,FIND("@",E24)),0)>0),"Valid","Invalid")) -> Valid | P24: =IF(TRIM(F24)="","Missing",IFERROR(IF(AND(ISNUMBER(--V24),OR(LEN(V24)=10,AND(LEN(V24)=12,LEFT(V24,2)="91")),VALUE(LEFT(RIGHT(V24,10),1))>=6),"Valid","Invalid"),"Invalid")) -> Valid | Q24: =IF(TRIM(G24)="","Missing",IFERROR(IF(AND(ISNUMBER(--TRIM(G24)),LEN(TRIM(G24))>=9,LEN(TRIM(G24))<=18,ISERROR(FIND(".",G24))),"Valid","Invalid"),"Invalid")) -> Valid | R24: =IF(TRIM(H24)="","Missing",IF(AND(LEN(TRIM(H24))=11,SUMPRODUCT(--(CODE(MID(TRIM(H24),{1,2,3,4},1))>=65),--(CODE(MID(TRIM(H24),{1,2,3,4},1))<=90))=4,MID(TRIM(H24),5,1)="0"),"Valid","Invalid")) -> Valid | S24: =IF(TRIM(I24)="","Missing",IF(EXACT(TRIM(I24),"India"),"Valid","Invalid")) -> Valid | T24: =IF(TRIM(J24)="","Missing",IF(OR(EXACT(TRIM(J24),"Net 15"),EXACT(TRIM(J24),"Net 30"),EXACT(TRIM(J24),"Net 45"),EXACT(TRIM(J24),"Net 60")),"Valid","Invalid")) -> Invalid | U24: =COUNTIF(M24:T24,"<>Valid") -> 2 | V24: =SUBSTITUTE(SUBSTITUTE(SUBSTITUTE(F24," ",""),"-",""),"+","") -> 6119393250 | W24: V1163 | X24: =IF(COUNTIF($W$2:$W$229,W24)>1,"Duplicate","Unique") -> Unique
A25: V1095 | B25: Unity Logistics LLP | C25: IMKCJ7226T | D25: 36IMKCJ7226T1Z6 | E25: ACCOUNTS@UNITYLOGISTICS.IN | F25: 88333-94522 | G25: 1587996846081 | H25: HDFC0620034 | I25: IN | J25: Net 30 | K25: Active | L25: 2021-10-23 | M25: =IF(TRIM(C25)="","Missing",IF(AND(LEN(TRIM(C25))=10,SUMPRODUCT(--(CODE(MID(TRIM(C25),{1,2,3,4,5,10},1))>=65),--(CODE(MID(TRIM(C25),{1,2,3,4,5,10},1))<=90))=6,ISNUMBER(--MID(TRIM(C25),6,4))),"Valid","Invalid")) -> Valid | N25: =IF(TRIM(D25)="","Missing",IF(AND(LEN(TRIM(D25))=15,MID(TRIM(D25),14,1)="Z"),IF(AND(TRIM(C25)<>"",MID(TRIM(D25),3,10)=TRIM(C25)),"Valid","PAN Mismatch"),"Invalid")) -> Valid | O25: =IF(TRIM(E25)="","Missing",IF(AND(ISNUMBER(FIND("@",E25)),ISERROR(FIND(" ",TRIM(E25))),IFERROR(FIND(".",E25,FIND("@",E25)),0)>0),"Valid","Invalid")) -> Valid | P25: =IF(TRIM(F25)="","Missing",IFERROR(IF(AND(ISNUMBER(--V25),OR(LEN(V25)=10,AND(LEN(V25)=12,LEFT(V25,2)="91")),VALUE(LEFT(RIGHT(V25,10),1))>=6),"Valid","Invalid"),"Invalid")) -> Valid | Q25: =IF(TRIM(G25)="","Missing",IFERROR(IF(AND(ISNUMBER(--TRIM(G25)),LEN(TRIM(G25))>=9,LEN(TRIM(G25))<=18,ISERROR(FIND(".",G25))),"Valid","Invalid"),"Invalid")) -> Valid | R25: =IF(TRIM(H25)="","Missing",IF(AND(LEN(TRIM(H25))=11,SUMPRODUCT(--(CODE(MID(TRIM(H25),{1,2,3,4},1))>=65),--(CODE(MID(TRIM(H25),{1,2,3,4},1))<=90))=4,MID(TRIM(H25),5,1)="0"),"Valid","Invalid")) -> Valid | S25: =IF(TRIM(I25)="","Missing",IF(EXACT(TRIM(I25),"India"),"Valid","Invalid")) -> Invalid | T25: =IF(TRIM(J25)="","Missing",IF(OR(EXACT(TRIM(J25),"Net 15"),EXACT(TRIM(J25),"Net 30"),EXACT(TRIM(J25),"Net 45"),EXACT(TRIM(J25),"Net 60")),"Valid","Invalid")) -> Valid | U25: =COUNTIF(M25:T25,"<>Valid") -> 1 | V25: =SUBSTITUTE(SUBSTITUTE(SUBSTITUTE(F25," ",""),"-",""),"+","") -> 8833394522 | W25: V1095 | X25: =IF(COUNTIF($W$2:$W$229,W25)>1,"Duplicate","Unique") -> Duplicate
A26: V1208 | B26: LOTUS ELECTRICALS L.L.P. | C26: JCUCU1076Z | E26: accounts@lotuselectricals.in | F26: 717350583 | G26: 17911006512070 | H26: SBIN1961108 | I26: India | J26: 15D | K26: Active | L26: 2024-12-25 | M26: =IF(TRIM(C26)="","Missing",IF(AND(LEN(TRIM(C26))=10,SUMPRODUCT(--(CODE(MID(TRIM(C26),{1,2,3,4,5,10},1))>=65),--(CODE(MID(TRIM(C26),{1,2,3,4,5,10},1))<=90))=6,ISNUMBER(--MID(TRIM(C26),6,4))),"Valid","Invalid")) -> Valid | N26: =IF(TRIM(D26)="","Missing",IF(AND(LEN(TRIM(D26))=15,MID(TRIM(D26),14,1)="Z"),IF(AND(TRIM(C26)<>"",MID(TRIM(D26),3,10)=TRIM(C26)),"Valid","PAN Mismatch"),"Invalid")) -> Missing | O26: =IF(TRIM(E26)="","Missing",IF(AND(ISNUMBER(FIND("@",E26)),ISERROR(FIND(" ",TRIM(E26))),IFERROR(FIND(".",E26,FIND("@",E26)),0)>0),"Valid","Invalid")) -> Valid | P26: =IF(TRIM(F26)="","Missing",IFERROR(IF(AND(ISNUMBER(--V26),OR(LEN(V26)=10,AND(LEN(V26)=12,LEFT(V26,2)="91")),VALUE(LEFT(RIGHT(V26,10),1))>=6),"Valid","Invalid"),"Invalid")) -> Invalid | Q26: =IF(TRIM(G26)="","Missing",IFERROR(IF(AND(ISNUMBER(--TRIM(G26)),LEN(TRIM(G26))>=9,LEN(TRIM(G26))<=18,ISERROR(FIND(".",G26))),"Valid","Invalid"),"Invalid")) -> Valid | R26: =IF(TRIM(H26)="","Missing",IF(AND(LEN(TRIM(H26))=11,SUMPRODUCT(--(CODE(MID(TRIM(H26),{1,2,3,4},1))>=65),--(CODE(MID(TRIM(H26),{1,2,3,4},1))<=90))=4,MID(TRIM(H26),5,1)="0"),"Valid","Invalid")) -> Invalid | S26: =IF(TRIM(I26)="","Missing",IF(EXACT(TRIM(I26),"India"),"Valid","Invalid")) -> Valid | T26: =IF(TRIM(J26)="","Missing",IF(OR(EXACT(TRIM(J26),"Net 15"),EXACT(TRIM(J26),"Net 30"),EXACT(TRIM(J26),"Net 45"),EXACT(TRIM(J26),"Net 60")),"Valid","Invalid")) -> Invalid | U26: =COUNTIF(M26:T26,"<>Valid") -> 4 | V26: =SUBSTITUTE(SUBSTITUTE(SUBSTITUTE(F26," ",""),"-",""),"+","") -> 717350583 | W26: V1197 | X26: =IF(COUNTIF($W$2:$W$229,W26)>1,"Duplicate","Unique") -> Duplicate
A27: V1173 | B27: Evergreen Logistics Limited | C27: IJCCY3432O | D27: 36CIMCJ3432O1ZU | E27: accounts@evergreenlogistics.in | F27: +91 64177 65612 | G27: 8156985700272 | H27: HDFC0634591 | I27: INDIA | J27: Net 15 | K27: Active | L27: 2024-10-16 | M27: =IF(TRIM(C27)="","Missing",IF(AND(LEN(TRIM(C27))=10,SUMPRODUCT(--(CODE(MID(TRIM(C27),{1,2,3,4,5,10},1))>=65),--(CODE(MID(TRIM(C27),{1,2,3,4,5,10},1))<=90))=6,ISNUMBER(--MID(TRIM(C27),6,4))),"Valid","Invalid")) -> Valid | N27: =IF(TRIM(D27)="","Missing",IF(AND(LEN(TRIM(D27))=15,MID(TRIM(D27),14,1)="Z"),IF(AND(TRIM(C27)<>"",MID(TRIM(D27),3,10)=TRIM(C27)),"Valid","PAN Mismatch"),"Invalid")) -> PAN Mismatch | O27: =IF(TRIM(E27)="","Missing",IF(AND(ISNUMBER(FIND("@",E27)),ISERROR(FIND(" ",TRIM(E27))),IFERROR(FIND(".",E27,FIND("@",E27)),0)>0),"Valid","Invalid")) -> Valid | P27: =IF(TRIM(F27)="","Missing",IFERROR(IF(AND(ISNUMBER(--V27),OR(LEN(V27)=10,AND(LEN(V27)=12,LEFT(V27,2)="91")),VALUE(LEFT(RIGHT(V27,10),1))>=6),"Valid","Invalid"),"Invalid")) -> Valid | Q27: =IF(TRIM(G27)="","Missing",IFERROR(IF(AND(ISNUMBER(--TRIM(G27)),LEN(TRIM(G27))>=9,LEN(TRIM(G27))<=18,ISERROR(FIND(".",G27))),"Valid","Invalid"),"Invalid")) -> Valid | R27: =IF(TRIM(H27)="","Missing",IF(AND(LEN(TRIM(H27))=11,SUMPRODUCT(--(CODE(MID(TRIM(H27),{1,2,3,4},1))>=65),--(CODE(MID(TRIM(H27),{1,2,3,4},1))<=90))=4,MID(TRIM(H27),5,1)="0"),"Valid","Invalid")) -> Valid | S27: =IF(TRIM(I27)="","Missing",IF(EXACT(TRIM(I27),"India"),"Valid","Invalid")) -> Invalid | T27: =IF(TRIM(J27)="","Missing",IF(OR(EXACT(TRIM(J27),"Net 15"),EXACT(TRIM(J27),"Net 30"),EXACT(TRIM(J27),"Net 45"),EXACT(TRIM(J27),"Net 60")),"Valid","Invalid")) -> Valid | U27: =COUNTIF(M27:T27,"<>Valid") -> 2 | V27: =SUBSTITUTE(SUBSTITUTE(SUBSTITUTE(F27," ",""),"-",""),"+","") -> 916417765612 | W27: V1173 | X27: =IF(COUNTIF($W$2:$W$229,W27)>1,"Duplicate","Unique") -> Unique
A28: V1042 | B28: Falcon IT Services Private Limited | C28: QRDCK3714O | D28: 29QRDCK3714O1ZJ | E28: accounts@falconitservices.in | F28: +91 64696 32595 | G28: 278774701687 | H28: ICIC0395004 | I28: India | J28: NET60 | K28: Active | L28: 2024-04-11 | M28: =IF(TRIM(C28)="","Missing",IF(AND(LEN(TRIM(C28))=10,SUMPRODUCT(--(CODE(MID(TRIM(C28),{1,2,3,4,5,10},1))>=65),--(CODE(MID(TRIM(C28),{1,2,3,4,5,10},1))<=90))=6,ISNUMBER(--MID(TRIM(C28),6,4))),"Valid","Invalid")) -> Valid | N28: =IF(TRIM(D28)="","Missing",IF(AND(LEN(TRIM(D28))=15,MID(TRIM(D28),14,1)="Z"),IF(AND(TRIM(C28)<>"",MID(TRIM(D28),3,10)=TRIM(C28)),"Valid","PAN Mismatch"),"Invalid")) -> Valid | O28: =IF(TRIM(E28)="","Missing",IF(AND(ISNUMBER(FIND("@",E28)),ISERROR(FIND(" ",TRIM(E28))),IFERROR(FIND(".",E28,FIND("@",E28)),0)>0),"Valid","Invalid")) -> Valid | P28: =IF(TRIM(F28)="","Missing",IFERROR(IF(AND(ISNUMBER(--V28),OR(LEN(V28)=10,AND(LEN(V28)=12,LEFT(V28,2)="91")),VALUE(LEFT(RIGHT(V28,10),1))>=6),"Valid","Invalid"),"Invalid")) -> Valid | Q28: =IF(TRIM(G28)="","Missing",IFERROR(IF(AND(ISNUMBER(--TRIM(G28)),LEN(TRIM(G28))>=9,LEN(TRIM(G28))<=18,ISERROR(FIND(".",G28))),"Valid","Invalid"),"Invalid")) -> Valid | R28: =IF(TRIM(H28)="","Missing",IF(AND(LEN(TRIM(H28))=11,SUMPRODUCT(--(CODE(MID(TRIM(H28),{1,2,3,4},1))>=65),--(CODE(MID(TRIM(H28),{1,2,3,4},1))<=90))=4,MID(TRIM(H28),5,1)="0"),"Valid","Invalid")) -> Valid | S28: =IF(TRIM(I28)="","Missing",IF(EXACT(TRIM(I28),"India"),"Valid","Invalid")) -> Valid | T28: =IF(TRIM(J28)="","Missing",IF(OR(EXACT(TRIM(J28),"Net 15"),EXACT(TRIM(J28),"Net 30"),EXACT(TRIM(J28),"Net 45"),EXACT(TRIM(J28),"Net 60")),"Valid","Invalid")) -> Invalid | U28: =COUNTIF(M28:T28,"<>Valid") -> 1 | V28: =SUBSTITUTE(SUBSTITUTE(SUBSTITUTE(F28," ",""),"-",""),"+","") -> 916469632595 | W28: V1042 | X28: =IF(COUNTIF($W$2:$W$229,W28)>1,"Duplicate","Unique") -> Unique
